Workbook

Sheet ICC PT
B2: CÁLCULO DAS INTENSIDADES DE CORRENTE ELÉCTRICA DE CURTO-CIRCUITO TRIFÁSICO E SIMÉTRICO NA ORIGEM DA INSTALAÇÃO ELÉCTRICA
B3: Grandeza a considerar | Q3: Valor
B4: Tensão nominal primária | P4: (Un1) | Q4: 30 | R4: kV
B5: Tensão nominal secundária | P5: (Un2) | Q5: 0.4 | R5: kV
B6: Número de transformadores a instalar no posto de transformação | P6: (ni) | Q6: 1
B7: Potência nominal dos transformadores | P7: (Snt) | Q7: 200 | R7: kVA
B8: Potência instalada | Q8: =Q7*Q6 -> 200 | R8: kVA
B9: Factor de tensão | P9: (c) | Q9: =IF(Q4<=1,1,1.1) -> 1.1
B10: Intensidade de corrente primária | Q10: =(Q8/(SQRT(3)*Q4)) -> 3.8490018 | R10: A
B11: Intensidade de corrente primária | Q11: =('ICC PT'!Q8/(SQRT(3)*'ICC PT'!Q5)) -> 288.67513 | R11: A
B12: Potência de curto-circuito na origem da instalação | P12: (Scc1) | Q12: 300 | R12: MVA
B13: Tensão de curto-circuito dos transformadores | P13: (εcc) | Q13: =IF(Q4>=24,5,IF(Q7<=630,4,4.5)) -> 5 | R13: %
B14: Corrente de curto-circuito trifásico e simétrico na origem da instalação | Q14: =(((Q12*10^6)/(SQRT(3)*(Q4*10^3)))/(10^3)) -> 5.7735027 | R14: kA
B15: Impedância de curto-circuito da rede eléctrica a montante da origem da instalação | Q15: =(Q9*((Q5*10^3)^2))/(Q12*10^6) -> 0.00058666667 | R15: Ω | AO15: =IF(OR(AL15="3G",AL15="5G"),"",VLOOKUP(AM15,Consulta!$Z$5:$AA$25,2,FALSE)) -> #N/A
B16: Impedância de curto-circuito dos transformadores de potência | Q16: =(Q13/100)*(((Q5*10^3)^2)/(Q7*10^3)) -> 0.04 | R16: Ω
B17: Impedância de curto-circuito ao secundário dos transformadores de potência | Q17: =(Q16/Q6)+Q15 -> 0.040586667 | R17: Ω
B18: Corrente de curto-circuito trifásico e simétrico ao secundário dos transformadores de potência | Q18: =(((Q5*10^3)/(SQRT(3)*Q17))/10^3) -> 5.6900486 | R18: kA | AO18: =IF(OR(AL18="3G",AL18="5G"),"",VLOOKUP(AM18,Consulta!$Z$5:$AA$25,2,FALSE)) -> #N/A
AO19: =IF(OR(AL19="3G",AL19="5G"),"",VLOOKUP(AM19,Consulta!$Z$5:$AA$25,2,FALSE)) -> #N/A
AO20: =IF(OR(AL20="3G",AL20="5G"),"",VLOOKUP(AM20,Consulta!$Z$5:$AA$25,2,FALSE)) -> #N/A
AO21: =IF(OR(AL21="3G",AL21="5G"),"",VLOOKUP(AM21,Consulta!$Z$5:$AA$25,2,FALSE)) -> #N/A
AO22: =IF(OR(AL22="3G",AL22="5G"),"",VLOOKUP(AM22,Consulta!$Z$5:$AA$25,2,FALSE)) -> #N/A
AO23: =IF(OR(AL23="3G",AL23="5G"),"",VLOOKUP(AM23,Consulta!$Z$5:$AA$25,2,FALSE)) -> #N/A
AO24: =IF(OR(AL24="3G",AL24="5G"),"",VLOOKUP(AM24,Consulta!$Z$5:$AA$25,2,FALSE)) -> #N/A
AO25: =IF(OR(AL25="3G",AL25="5G"),"",VLOOKUP(AM25,Consulta!$Z$5:$AA$25,2,FALSE)) -> #N/A
AO26: =IF(OR(AL26="3G",AL26="5G"),"",VLOOKUP(AM26,Consulta!$Z$5:$AA$25,2,FALSE)) -> #N/A
AO27: =IF(OR(AL27="3G",AL27="5G"),"",VLOOKUP(AM27,Consulta!$Z$5:$AA$25,2,FALSE)) -> #N/A
AO28: =IF(OR(AL28="3G",AL28="5G"),"",VLOOKUP(AM28,Consulta!$Z$5:$AA$25,2,FALSE)) -> #N/A
AO29: =IF(OR(AL29="3G",AL29="5G"),"",VLOOKUP(AM29,Consulta!$Z$5:$AA$25,2,FALSE)) -> #N/A
AO30: =IF(OR(AL30="3G",AL30="5G"),"",VLOOKUP(AM30,Consulta!$Z$5:$AA$25,2,FALSE)) -> #N/A
... AO43: =IF(OR(AL43="3G",AL43="5G"),"",VLOOKUP(AM43,Consulta!$Z$5:$AA$25,2,FALSE)) -> #N/A

Sheet ICC GS
B2: CÁLCULO DAS INTENSIDADES DE CORRENTE ELÉCTRICA DE CURTO-CIRCUITO TRIFÁSICO E SIMÉTRICO NA ORIGEM DA INSTALAÇÃO ELÉCTRICA ABASTECIDA POR GERADOR DE SOCORRO
B3: Grandeza a considerar | J3: Valor
B4: Tensão nominal | I4: (Un) | J4: 0.4 | K4: kV
B5: Número de geradores de socorro a instalar | I5: (nG) | J5: 1
B6: Potência nominal dos geradores de socorro | I6: (SnG) | J6: 170 | K6: kVA
B7: Potência instalada | J7: =J6*J5 -> 170 | K7: kVA
B8: Factor de tensão | I8: (c)
B9: Reactância sub-transitória dos geradores | I9: (Xd") | K9: %
B10: Impedância de curto-circuito dos geradores de socorro | J10: =(J9/100)*(((J4*10^3)^2)/(J6*10^3)) -> 0 | K10: Ω
B11: Corrente de curto-circuito trifásico e simétrico aos terminais do gerador de socorro | J11: =(((J4*10^3)/(SQRT(3)*J10))/10^3) -> #DIV/0! | K11: kA

Sheet Fusíveis MT
B2: DIMENSIONAMENTO DOS FUSÍVEIS DE MT
B3: Grandeza a considerar | Q3: Valor
B4: Intensidade de corrente primária | Q4: =('ICC PT'!Q7/(SQRT(3)*'ICC PT'!Q4)) -> 3.8490018 | R4: A
B5: Intensidade de corrente primária | Q5: =('ICC PT'!Q7/(SQRT(3)*'ICC PT'!Q5)) -> 288.67513 | R5: A
B6: Factor m | Q6: ='ICC PT'!Q4/'ICC PT'!Q5 -> 75
B7: Intensidade de corrente nominal (ou regulada) da protecção mais alta do lado de Baixa Tensão | P7: (IBT) | Q7: 577 | R7: A
B8: Coeficiente de coordenação MT/BT (1,4 para IBT < 315 e 1,6 para IBT ≥ 315A) | P8: (kc) | Q8: =IF(Q7<315,1.4,1.6) -> 1.6
B9: Condição 1: Para IA, o tempo de fusão deverá ser ≥ 40ms | Q9: =8*Q4 -> 30.792014 | R9: A
Q10: 16 | R10: A
B24: Condição 2: O calibre dos fusíveis deverá ser menor que 3,33 vezes a corrente primária | Q24: =3.33*Q4 -> 12.817176 | R24: A
B25: Condição 3: O calibre dos fusíveis deverá ser maior que 1,3 vezes a corrente primária | Q25: =1.3*Q4 -> 5.0037023 | R25: A
B26: Condição 4: O calibre dos fusíveis deverá ser maior que: | Q26: =(Q8*Q7)/Q6 -> 12.309333 | R26: A
B27: Calibre dos fusíveis a adoptar: | Q27: =VLOOKUP(1,$F$38:$G$51,2,FALSE) -> #N/A | R27: A
B33: Condição 1 | C33: Condição 2 | D33: Condição 3 | E33: Condição 4 | F33: Verif Final | G33: Calibres normalizados [A]
B38: =IF(G38>$Q$10,1,0) -> 0 | C38: =IF(G38<$Q$24,1,0) -> 1 | D38: =IF(G38>$Q$25,1,0) -> 1 | E38: =IF(G38>$Q$26,1,0) -> 0 | F38: =IF(AND(B38=1,C38=1,D38=1,E38=1),1,0) -> 0 | G38: 6.3
B39: =IF(G39>$Q$10,1,0) -> 0 | C39: =IF(G39<$Q$24,1,0) -> 1 | D39: =IF(G39>$Q$25,1,0) -> 1 | E39: =IF(G39>$Q$26,1,0) -> 0 | F39: =IF(AND(B39=1,C39=1,D39=1,E39=1),1,0) -> 0 | G39: 10
B40: =IF(G40>$Q$10,1,0) -> 0 | C40: =IF(G40<$Q$24,1,0) -> 0 | D40: =IF(G40>$Q$25,1,0) -> 1 | E40: =IF(G40>$Q$26,1,0) -> 1 | F40: =IF(AND(B40=1,C40=1,D40=1,E40=1),1,0) -> 0 | G40: 16
B41: =IF(G41>$Q$10,1,0) -> 1 | C41: =IF(G41<$Q$24,1,0) -> 0 | D41: =IF(G41>$Q$25,1,0) -> 1 | E41: =IF(G41>$Q$26,1,0) -> 1 | F41: =IF(AND(B41=1,C41=1,D41=1,E41=1),1,0) -> 0 | G41: 20
B42: =IF(G42>$Q$10,1,0) -> 1 | C42: =IF(G42<$Q$24,1,0) -> 0 | D42: =IF(G42>$Q$25,1,0) -> 1 | E42: =IF(G42>$Q$26,1,0) -> 1 | F42: =IF(AND(B42=1,C42=1,D42=1,E42=1),1,0) -> 0 | G42: 25
B43: =IF(G43>$Q$10,1,0) -> 1 | C43: =IF(G43<$Q$24,1,0) -> 0 | D43: =IF(G43>$Q$25,1,0) -> 1 | E43: =IF(G43>$Q$26,1,0) -> 1 | F43: =IF(AND(B43=1,C43=1,D43=1,E43=1),1,0) -> 0 | G43: 31.5
B44: =IF(G44>$Q$10,1,0) -> 1 | C44: =IF(G44<$Q$24,1,0) -> 0 | D44: =IF(G44>$Q$25,1,0) -> 1 | E44: =IF(G44>$Q$26,1,0) -> 1 | F44: =IF(AND(B44=1,C44=1,D44=1,E44=1),1,0) -> 0 | G44: 40
B45: =IF(G45>$Q$10,1,0) -> 1 | C45: =IF(G45<$Q$24,1,0) -> 0 | D45: =IF(G45>$Q$25,1,0) -> 1 | E45: =IF(G45>$Q$26,1,0) -> 1 | F45: =IF(AND(B45=1,C45=1,D45=1,E45=1),1,0) -> 0 | G45: 50
B46: =IF(G46>$Q$10,1,0) -> 1 | C46: =IF(G46<$Q$24,1,0) -> 0 | D46: =IF(G46>$Q$25,1,0) -> 1 | E46: =IF(G46>$Q$26,1,0) -> 1 | F46: =IF(AND(B46=1,C46=1,D46=1,E46=1),1,0) -> 0 | G46: 63
B47: =IF(G47>$Q$10,1,0) -> 1 | C47: =IF(G47<$Q$24,1,0) -> 0 | D47: =IF(G47>$Q$25,1,0) -> 1 | E47: =IF(G47>$Q$26,1,0) -> 1 | F47: =IF(AND(B47=1,C47=1,D47=1,E47=1),1,0) -> 0 | G47: 80
B48: =IF(G48>$Q$10,1,0) -> 1 | C48: =IF(G48<$Q$24,1,0) -> 0 | D48: =IF(G48>$Q$25,1,0) -> 1 | E48: =IF(G48>$Q$26,1,0) -> 1 | F48: =IF(AND(B48=1,C48=1,D48=1,E48=1),1,0) -> 0 | G48: 100
B49: =IF(G49>$Q$10,1,0) -> 1 | C49: =IF(G49<$Q$24,1,0) -> 0 | D49: =IF(G49>$Q$25,1,0) -> 1 | E49: =IF(G49>$Q$26,1,0) -> 1 | F49: =IF(AND(B49=1,C49=1,D49=1,E49=1),1,0) -> 0 | G49: 125
... B51: =IF(G51>$Q$10,1,0) -> 1 | C51: =IF(G51<$Q$24,1,0) -> 0 | D51: =IF(G51>$Q$25,1,0) -> 1 | E51: =IF(G51>$Q$26,1,0) -> 1 | F51: =IF(AND(B51=1,C51=1,D51=1,E51=1),1,0) -> 0 | G51: 200

Sheet Bacia Rentenção
B2: DIMENSIONAMENTO DA BACIA DE RENTENÇÃO EM CASO DE ESCORRÊNCIA DO ÓLEO DO TRANSFORMADOR DE POTÊNCIA
B3: Grandeza a considerar | J3: Valor
B4: Massa total de óleo do(s) transformador(es) | I4: (m) | J4: 270 | K4: kg
B5: Massa volúmica do óleo mineral utilizado nos transformadores | I5: (ρ) | J5: 900 | K5: kg/m3 | M5: https://oilregeneration.globecore.com/transformer-oil-density-and-viscosity.html
B6: Volume necessário para albergar o óleo do(s) transformador(es) | J6: =J4/J5 -> 0.3 | K6: m3
B7: Formato do reservatório | J7: Prisma Quadrangular
B8: =IF(J7="Prisma Quadrangular","Comprimento e Largura pretendidos","Diâmetro pretendido") -> Comprimento e Largura pretendidos | J8: 1 | K8: m
B9: Altura mínima necessária | J9: =IF(J7="Prisma Quadrangular",J6/J8/J8,J6/((PI()*J8^2)/4)) -> 0.3 | K9: m

Sheet Ventilação PT
B2: DIMENSIONAMENTO GRELHAS DE VENTILAÇÃO NATURAL PARA POSTOS DE TRANSFORMAÇÃO
B3: Grandeza a considerar | E3: Valor
B4: Nível de tensão primário | E4: ='ICC PT'!Q4 -> 30 | F4: kV
B5: Potência do(s) transformador(es) | E5: ='ICC PT'!Q8 -> 200 | F5: kVA
B6: Tipo de Transformador | E6: Banho de Óleo
B7: Perdas em vazio | D7: (p0) | E7: =IF(AND($E$4<=24,$E$6="Banho de Óleo"),VLOOKUP($E$5,Consulta!$BS$6:$BW$20,2,FALSE),IF(AND($E$4>24,$E$6="Banho de Óleo"),VLOOKUP($E$5,Consulta!$BS$6:$BW$20,4,FALSE),IF(AND($E$4<=24,$E$6="Seco"),VLOOKUP($E$5,Consulta!$BY$6:$CC$20,2,FALSE),IF(AND($E$4>24,$E$6="Seco"),VLOOKUP($E$5,Consulta!$BY$6:$CC$20,4,FALSE))))) -> 0.7 | F7: kW
B8: Perdas em carga | D8: (pcw) | E8: =IF(AND($E$4<=24,$E$6="Banho de Óleo"),VLOOKUP($E$5,Consulta!$BS$6:$BW$20,3,FALSE),IF(AND($E$4>24,$E$6="Banho de Óleo"),VLOOKUP($E$5,Consulta!$BS$6:$BW$20,5,FALSE),IF(AND($E$4<=24,$E$6="Seco"),VLOOKUP($E$5,Consulta!$BY$6:$CC$20,3,FALSE),IF(AND($E$4>24,$E$6="Seco"),VLOOKUP($E$5,Consulta!$BY$6:$CC$20,5,FALSE))))) -> 3.6 | F8: kW
B9: Época mais quente do ano | E9: Verão
B10: Caraterísticas das zona abastecida | E10: Industrial
B11: Tipo de Posto de Transformação | E11: Cabine Baixa
B12: Altura do Posto de Transformação | D12: (H) | E12: =VLOOKUP($E$11,Consulta!$CE$15:$CI$16,2,FALSE) -> 3 | F12: m | H12: Pode modificar manualmente!
B13: Coeficiente de sobrecarga | D13: (c) | E13: =IF($E$9="Inverno",VLOOKUP($E$10,Consulta!$CE$6:$CI$10,2,FALSE),IF($E$9="Verão",VLOOKUP($E$10,Consulta!$CE$6:$CI$10,4,FALSE))) -> 0.8
B14: Diferença de temperatura entre o ar interior (considerado a 40ºC) e o ar exterior | D14: (∆θ) | E14: =IF($E$9="Inverno",VLOOKUP($E$10,Consulta!$CE$6:$CI$10,3,FALSE),IF($E$9="Verão",VLOOKUP($E$10,Consulta!$CE$6:$CI$10,5,FALSE))) -> 12 | F14: ºC
B15: Secção mínima de abertura das grelhas de ventilação: | E15: =((10*(E7+((E13^2)*E8)))/SQRT((E12-1.2)*(E14^3))) -> 0.53863157 | F15: m2
B16: Aberturas de entrada | C16: Altura pretendida | D16: (HE) | E16: 0.65 | F16: m
C17: Largura necessária | D17: (LE) | E17: =E15/E16 -> 0.82866396 | F17: m | H17: Se pretender, pode trocar a largura com a altura
B18: Aberturas de saída | C18: Altura pretendida | D18: (HS) | E18: 0.75 | F18: m
C19: Largura necessária | D19: (LS) | E19: =E15/E18 -> 0.71817543 | F19: m

Sheet Terras
B2: DIMENSIONAMENTO DE ELÉTRODOS DE TERRA
B3: Caso o instalador opte pela instalação de varetas:
B4: Grandeza a considerar | E4: Valor
B5: Tipo de elétrodo | E5: Vareta ou tubo
B6: Número de elétrodos | D6: (n) | E6: 7
B7: Resistividade do solo | D7: (ρs) | E7: 100 | F7: Ω.m
B8: Comprimento do elétrodo | D8: (L) | E8: 1.75 | F8: m
B9: Diâmetro do elétrodo | D9: (d) | E9: 0.05 | F9: m
B10: Distância entre elétrodos | D10: (D) | E10: 5 | F10: m
B11: Profundidade de enterramento da parte superior do elétrodo (deverá ser igual ou superior a 0,8m) | D11: (pe) | E11: 2 | F11: m
B12: Resistência elétrica de contato à terra (editar fórmula): | E12: =(1/E6)*(((E7/(2*PI()*E8))*LN(((4*E8)/(E9/2))-1))+((E7/(PI()*E10))*(1/2+1/3+1/4+1/5+1/6+1/7))) -> 8.7648404 | F12: Ω
B15: Caso o instalador opte pela instalação de chapas retangulares enterradas verticalmente
B16: Grandeza a considerar | E16: Valor
B17: Tipo de elétrodo | E17: Chapa retangular enterrada verticalmente
B18: Número de elétrodos | D18: (n) | E18: 4
B19: Distância entre elétrodos | D19: (D) | E19: 5 | F19: m
B20: Resistividade do solo | D20: (ρs) | E20: 100 | F20: Ω.m
B21: Comprimento do elétrodo | D21: (a) | E21: 1 | F21: m
B22: Largura do elétrodo | D22: (b) | E22: 1 | F22: m
B23: Profundidade de enterramento da parte superior do elétrodo (deverá ser igual ou superior a 0,8m) | D23: (pe) | E23: 2 | F23: m
B24: Resistência elétrica de contato à terra: Para 1 elétrodo (R1), para vários elétrodos (R(n)) | E24: =IF(E18=1,((0.4*E20)/(E21+E22))*(1+((E21+E22)/(E21+E22+(8*(E23+(E22/2)))))),(((0.16*E20)/E18)*((((0.4*E20)/(E21+E22))*(1+((E21+E22)/(E21+E22+(8*(E23+(E22/2))))))/(0.16*E20))+((E18-1)/E19)))) -> 7.8545455 | F24: Ω
B25: Superfície de contato à terra (deverá ser superior a 1m2) | E25: =E18*(2*E21*E22) -> 8 | F25: m2

Sheet Canalizações e Proteções
B1: DIMENSIONAMENTO DAS CANALIZAÇÕES E ÓRGÃOS DE PROTECÇÃO PRINCIPAIS | BA1: Valores das Intensidades de Corrente Máxima Admissível segundo as RTIEBT, mediante o material constituinte do isolamento dos condutores e os seguintes métodos de referência: | BY1: Diâmetro dos tubos a instalar mediante o tipo de canalização e o fim a que se destina:
B2: Quadro | C2: Circuito | D2: Potência nominal do circuito [kW] | E2: L [m] | F2: Tipo de circuito | G2: Tipo de Cabo (se aplicável) | H2: f.p. (cosφ) | I2: Tipo de condutores e fim ao que se destinam | J2: Material condutor | K2: Material do isolamento do condutor | L2: N.º de cabos em paralelo | M2: Secção [mm2] | N2: Método de referência | O2: Modo de Instalação | P2: Iz [A] | Q2: N.º de cabos agrup. | R2: Factor de correcção ao Iz | S2: Ib [A] | T2: Iz' (Corrigido) [A] | U2: Dispositivo de protecção | V2: In [A] | W2: I2 [A] | X2: 1,45×Iz [A] | Y2: Condições a verificar | AA2: Impedância a montante [W] | AB2: Resistência condutores (R) [W] | AC2: Reactância condutores (X) [W] | AD2: Queda de tensão a montante [V] | AE2: Queda de tensão relativa (e) [V] | AF2: Queda de tensão acumulada (e') [V] | AG2: Queda de tensão relativa (DU) [%] | AH2: Queda de tensão acumulada (DU') [%] | AI2: Icc máximo (no final desta canalização) [kA] | AJ2: Poder de corte a instalar [kA] | AK2: Tempo de corte máximo do órgão de protecção [s] | AL2: Coeficiente K | AM2: Secção mínima (smin) para suportar a fadiga térmica [mm2] | AN2: Condutor | BA2: PVC | BJ2: XLPE/EPR | BS2: Mineral | BW2: N.º linha | BY2: Canalizações | CC2: Colunas/Entradas
Y3: Ib/Iz [%] | Z3: Ib ≤ In ≤ Iz e I2 ≤ 1,45 Iz | BA3: A | BB3: A2 | BC3: B | BD3: B2 | BE3: C | BF3: D | BG3: E | BH3: F | BI3: G | BJ3: A | BK3: A2 | BL3: B | BM3: B2 | BN3: C | BO3: D | BP3: E | BQ3: F | BR3: G | BS3: C | BT3: E | BU3: F | BV3: G | BY3: Fio / Monofásico | BZ3: Fio / Trifásico | CA3: Cabo / Monofásico | CB3: Cabo / Trifásico | CC3: Fio / Monofásico | CD3: Fio / Trifásico | CE3: Cabo / Monofásico | CF3: Cabo / Trifásico
B4: Transformador | C4: Q.G.B.T. / Q.E. | D4: =SUM(D5:D11)*0.4*1.2 -> 117.63984 | E4: 1 | F4: Trifásico | G4: Monocondutor | H4: 1 | I4: Cabo/Canalizações | J4: Cobre | K4: PVC | L4: 2 | M4: 25 | N4: F | O4: 5A | P4: =IF(K4="PVC",HLOOKUP(N4,$BA$3:$BI$17,BW4,FALSE),IF(OR(K4="XLPE",K4="EPR"),HLOOKUP(N4,$BJ$3:$BR$17,BW4,FALSE),IF(K4="Mineral",HLOOKUP(N4,$BS$3:$BV$17,BW4,FALSE),"N/A")))*L4 -> 220 | Q4: 1 | R4: 1 | S4: =IF(F4="Monofásico",(((D4*10^3)/H4)/230),(((D4*10^3)/H4)/(SQRT(3)*400))) -> 169.79848 | T4: =P4*R4 -> 220 | U4: - | V4: - | W4: - | X4: - | Y4: =S4/T4 -> 0.77181129 | Z4: - | AA4: ='ICC PT'!Q17 -> 0.040586667 | AB4: =(IF(J4="Cobre",(1.25*0.0225),(1.25*0.036)))*((E4/M4)/L4) -> 0.0005625 | AC4: =(IF(M4<10,0,(0.00008)))*(E4) -> 8e-05 | AD4: 0 | AE4: =IF(F4="Trifásico",S4*((AB4*H4)+(AC4*SIN(ACOS(H4)))),2*S4*(AB4*H4+AC4*SIN(ACOS(H4)))) -> 0.095511647 | AF4: =AD4+AE4 -> 0.095511647 | AG4: =AE4/230 -> 0.00041526803 | AH4: =AF4/230 -> 0.00041526803 | AI4: =IF(F4="Monofásico",(0.23/(SQRT((AB4^2)+(AC4^2))+AA4)),(0.4/(SQRT(3)*(SQRT((AB4^2)+(AC4^2))+AA4)))) -> 5.611495 | AJ4: 6 | AK4: 0.1 | AL4: =IF(G4="Multicondutor",(IF(AND(J4="Cobre",K4="PVC"),115,IF(AND(J4="Cobre",K4="XLPE"),143,IF(AND(J4="Alumínio",K4="PVC"),76,IF(AND(J4="Alumínio",K4="XLPE"),94))))),(IF(AND(J4="Cobre",K4="PVC"),143,IF(AND(J4="Cobre",K4="XLPE"),176,IF(AND(J4="Alumínio",K4="PVC"),95,IF(AND(J4="Alumínio",K4="XLPE"),116)))))) -> 143 | AM4: =((AI4*1000)*SQRT(AK4))/AL4 -> 12.409165 | AN4: =L4 -> 2 | AO4: × | AP4: [XV | AQ4: =IF(F4="Monofásico","3G",IF(AND(F4="Trifásico",M4<25),"5G","3×")) -> 3× | AR4: =M4 -> 25 | BA4: =IF(AND(J4="Cobre",F4="Monofásico"),VLOOKUP(M4,'Iz''s'!$B$8:$E$23,2,FALSE),IF(AND(J4="Cobre",F4="Trifásico"),VLOOKUP(M4,'Iz''s'!$L$8:$O$23,2,FALSE),IF(AND(J4="Alumínio",F4="Monofásico"),VLOOKUP(M4,'Iz''s'!$B$25:$E$39,2,FALSE),IF(AND(J4="Alumínio",F4="Trifásico"),VLOOKUP(M4,'Iz''s'!$L$25:$O$39,2,FALSE))))) -> 73 | BB4: =IF(AND(J4="Cobre",F4="Monofásico"),VLOOKUP(M4,'Iz''s'!$CD$9:$CH$24,2,FALSE),IF(AND(J4="Cobre",F4="Trifásico"),VLOOKUP(M4,'Iz''s'!$CD$9:$CH$24,4,FALSE),IF(AND(J4="Alumínio",F4="Monofásico"),VLOOKUP(M4,'Iz''s'!$CD$26:$CH$40,2,FALSE),IF(AND(J4="Alumínio",F4="Trifásico"),VLOOKUP(M4,'Iz''s'!$CD$26:$CH$40,4,FALSE))))) -> 68 | BC4: =IF(AND(J4="Cobre",F4="Monofásico"),VLOOKUP(M4,'Iz''s'!$B$8:$E$23,3,FALSE),IF(AND(J4="Cobre",F4="Trifásico"),VLOOKUP(M4,'Iz''s'!$L$8:$O$23,3,FALSE),IF(AND(J4="Alumínio",F4="Monofásico"),VLOOKUP(M4,'Iz''s'!$B$25:$E$39,3,FALSE),IF(AND(J4="Alumínio",F4="Trifásico"),VLOOKUP(M4,'Iz''s'!$L$25:$O$39,3,FALSE))))) -> 89 | BD4: =IF(AND(J4="Cobre",F4="Monofásico"),VLOOKUP(M4,'Iz''s'!$CD$9:$CH$24,3,FALSE),IF(AND(J4="Cobre",F4="Trifásico"),VLOOKUP(M4,'Iz''s'!$CD$9:$CH$24,5,FALSE),IF(AND(J4="Alumínio",F4="Monofásico"),VLOOKUP(M4,'Iz''s'!$CD$26:$CH$40,3,FALSE),IF(AND(J4="Alumínio",F4="Trifásico"),VLOOKUP(M4,'Iz''s'!$CD$26:$CH$40,5,FALSE))))) -> 80 | BE4: =IF(AND(J4="Cobre",F4="Monofásico"),VLOOKUP(M4,'Iz''s'!$B$8:$E$23,4,FALSE),IF(AND(J4="Cobre",F4="Trifásico"),VLOOKUP(M4,'Iz''s'!$L$8:$O$23,4,FALSE),IF(AND(J4="Alumínio",F4="Monofásico"),VLOOKUP(M4,'Iz''s'!$B$25:$E$39,4,FALSE),IF(AND(J4="Alumínio",F4="Trifásico"),VLOOKUP(M4,'Iz''s'!$L$25:$O$39,4,FALSE))))) -> 96 | BF4: =IF(AND(J4="Cobre",F4="Monofásico"),VLOOKUP(M4,'Iz''s'!$CP$9:$CT$24,3,FALSE),IF(AND(J4="Cobre",F4="Trifásico"),VLOOKUP(M4,'Iz''s'!$CP$9:$CT$24,2,FALSE),IF(AND(J4="Alumínio",F4="Monofásico"),VLOOKUP(M4,'Iz''s'!$CP$26:$CT$37,3,FALSE),IF(AND(J4="Alumínio",F4="Trifásico"),VLOOKUP(M4,'Iz''s'!$CP$26:$CT$37,2,FALSE))))) -> 123 | BG4: =IF(AND(J4="Cobre",F4="Monofásico"),VLOOKUP(M4,'Iz''s'!$AT$10:$BA$28,2,FALSE),IF(AND(J4="Cobre",F4="Trifásico"),VLOOKUP(M4,'Iz''s'!$AT$10:$BA$28,3,FALSE),IF(AND(J4="Alumínio",F4="Monofásico"),VLOOKUP(M4,'Iz''s'!$BC$10:$BJ$27,2,FALSE),IF(AND(J4="Alumínio",F4="Trifásico"),VLOOKUP(M4,'Iz''s'!$BC$10:$BJ$27,3,FALSE))))) -> 101 | BH4: =IF(AND(J4="Cobre",F4="Monofásico"),VLOOKUP(M4,'Iz''s'!$AT$10:$BA$28,4,FALSE),IF(AND(J4="Cobre",F4="Trifásico"),VLOOKUP(M4,'Iz''s'!$AT$10:$BA$28,5,FALSE),IF(AND(J4="Alumínio",F4="Monofásico"),VLOOKUP(M4,'Iz''s'!$BC$10:$BJ$27,4,FALSE),IF(AND(J4="Alumínio",F4="Trifásico"),VLOOKUP(M4,'Iz''s'!$BC$10:$BJ$27,5,FALSE))))) -> 110 | BI4: =IF(AND(J4="Cobre",F4="Monofásico"),"N/A",IF(AND(J4="Cobre",F4="Trifásico"),VLOOKUP(M4,'Iz''s'!$AT$10:$BA$28,8,FALSE),IF(AND(J4="Alumínio",F4="Monofásico"),"N/A",IF(AND(J4="Alumínio",F4="Trifásico"),VLOOKUP(M4,'Iz''s'!$BC$10:$BJ$27,8,FALSE))))) -> 130 | BJ4: =IF(AND(J4="Cobre",F4="Monofásico"),VLOOKUP(M4,'Iz''s'!$G$8:$J$23,2,FALSE),IF(AND(J4="Cobre",F4="Trifásico"),VLOOKUP(M4,'Iz''s'!$Q$8:$T$23,2,FALSE),IF(AND(J4="Alumínio",F4="Monofásico"),VLOOKUP(M4,'Iz''s'!$G$25:$J$39,2,FALSE),IF(AND(J4="Alumínio",F4="Trifásico"),VLOOKUP(M4,'Iz''s'!$Q$25:$T$39,2,FALSE))))) -> 95 | BK4: =IF(AND(J4="Cobre",F4="Monofásico"),VLOOKUP(M4,'Iz''s'!$CJ$9:$CN$24,2,FALSE),IF(AND(J4="Cobre",F4="Trifásico"),VLOOKUP(M4,'Iz''s'!$CJ$9:$CN$24,4,FALSE),IF(AND(J4="Alumínio",F4="Monofásico"),VLOOKUP(M4,'Iz''s'!$CJ$26:$CN$40,2,FALSE),IF(AND(J4="Alumínio",F4="Trifásico"),VLOOKUP(M4,'Iz''s'!$CJ$26:$CN$40,4,FALSE))))) -> 89 | BL4: =IF(AND(J4="Cobre",F4="Monofásico"),VLOOKUP(M4,'Iz''s'!$G$8:$J$23,3,FALSE),IF(AND(J4="Cobre",F4="Trifásico"),VLOOKUP(M4,'Iz''s'!$Q$8:$T$23,3,FALSE),IF(AND(J4="Alumínio",F4="Monofásico"),VLOOKUP(M4,'Iz''s'!$G$25:$J$39,3,FALSE),IF(AND(J4="Alumínio",F4="Trifásico"),VLOOKUP(M4,'Iz''s'!$Q$25:$T$39,3,FALSE))))) -> 117 | BM4: =IF(AND(J4="Cobre",F4="Monofásico"),VLOOKUP(M4,'Iz''s'!$CJ$9:$CN$24,3,FALSE),IF(AND(J4="Cobre",F4="Trifásico"),VLOOKUP(M4,'Iz''s'!$CJ$9:$CN$24,5,FALSE),IF(AND(J4="Alumínio",F4="Monofásico"),VLOOKUP(M4,'Iz''s'!$CJ$26:$CN$40,3,FALSE),IF(AND(J4="Alumínio",F4="Trifásico"),VLOOKUP(M4,'Iz''s'!$CJ$26:$CN$40,5,FALSE))))) -> 105 | BN4: =IF(AND(J4="Cobre",F4="Monofásico"),VLOOKUP(M4,'Iz''s'!$G$8:$J$23,4,FALSE),IF(AND(J4="Cobre",F4="Trifásico"),VLOOKUP(M4,'Iz''s'!$Q$8:$T$23,4,FALSE),IF(AND(J4="Alumínio",F4="Monofásico"),VLOOKUP(M4,'Iz''s'!$G$25:$J$39,4,FALSE),IF(AND(J4="Alumínio",F4="Trifásico"),VLOOKUP(M4,'Iz''s'!$Q$25:$T$39,4,FALSE))))) -> 119 | BO4: =IF(AND(J4="Cobre",F4="Monofásico"),VLOOKUP(M4,'Iz''s'!$CP$9:$CT$24,5,FALSE),IF(AND(J4="Cobre",F4="Trifásico"),VLOOKUP(M4,'Iz''s'!$CP$9:$CT$24,4,FALSE),IF(AND(J4="Alumínio",F4="Monofásico"),VLOOKUP(M4,'Iz''s'!$CP$26:$CT$37,5,FALSE),IF(AND(J4="Alumínio",F4="Trifásico"),VLOOKUP(M4,'Iz''s'!$CP$26:$CT$37,4,FALSE))))) -> 144 | BP4: =IF(AND(J4="Cobre",F4="Monofásico"),VLOOKUP(M4,'Iz''s'!$BL$10:$BS$28,2,FALSE),IF(AND(J4="Cobre",F4="Trifásico"),VLOOKUP(M4,'Iz''s'!$BL$10:$BS$28,3,FALSE),IF(AND(J4="Alumínio",F4="Monofásico"),VLOOKUP(M4,'Iz''s'!$BU$10:$CB$27,2,FALSE),IF(AND(J4="Alumínio",F4="Trifásico"),VLOOKUP(M4,'Iz''s'!$BU$10:$CB$27,3,FALSE))))) -> 127 | BQ4: =IF(AND(J4="Cobre",F4="Monofásico"),VLOOKUP(M4,'Iz''s'!$BL$10:$BS$28,4,FALSE),IF(AND(J4="Cobre",F4="Trifásico"),VLOOKUP(M4,'Iz''s'!$BL$10:$BS$28,5,FALSE),IF(AND(J4="Alumínio",F4="Monofásico"),VLOOKUP(M4,'Iz''s'!$BU$10:$CB$27,4,FALSE),IF(AND(J4="Alumínio",F4="Trifásico"),VLOOKUP(M4,'Iz''s'!$BU$10:$CB$27,5,FALSE))))) -> 135 | BR4: =IF(AND(J4="Cobre",F4="Monofásico"),"N/A",IF(AND(J4="Cobre",F4="Trifásico"),VLOOKUP(M4,'Iz''s'!$BL$10:$BS$28,8,FALSE),IF(AND(J4="Alumínio",F4="Monofásico"),"N/A",IF(AND(J4="Alumínio",F4="Trifásico"),VLOOKUP(M4,'Iz''s'!$BU$10:$CB$27,8,FALSE))))) -> 161 | BS4: =IF(AND(K4="Cobre",G4="Monofásico"),"N/A",IF(AND(K4="Cobre",G4="Trifásico"),VLOOKUP(N4,'Iz''s'!$BL$10:$BS$28,8,FALSE),IF(AND(K4="Alumínio",G4="Monofásico"),"N/A",IF(AND(K4="Alumínio",G4="Trifásico"),VLOOKUP(N4,'Iz''s'!$BU$10:$CB$27,8,FALSE))))) -> FALSE | BT4: =IF(AND(J4="Cobre",F4="Monofásico"),VLOOKUP(M4,'Iz''s'!$AF$15:$AK$29,2,FALSE),IF(AND(J4="Cobre",F4="Trifásico"),VLOOKUP(M4,'Iz''s'!$AF$15:$AK$29,3,FALSE),IF(AND(J4="Alumínio",F4="Monofásico"),"N/A",IF(AND(J4="Alumínio",F4="Trifásico"),"N/A")))) -> 120 | BU4: =IF(AND(J4="Cobre",F4="Monofásico"),VLOOKUP(M4,'Iz''s'!$AF$15:$AK$29,2,FALSE),IF(AND(J4="Cobre",F4="Trifásico"),VLOOKUP(M4,'Iz''s'!$AF$15:$AK$29,3,FALSE),IF(AND(J4="Alumínio",F4="Monofásico"),"N/A",IF(AND(J4="Alumínio",F4="Trifásico"),"N/A")))) -> 120 | BV4: =IF(AND(J4="Cobre",F4="Monofásico"),"N/A",IF(AND(J4="Cobre",F4="Trifásico"),VLOOKUP(M4,'Iz''s'!$AF$15:$AK$29,6,FALSE),IF(AND(J4="Alumínio",F4="Monofásico"),"N/A",IF(AND(J4="Alumínio",F4="Trifásico"),"N/A")))) -> 162 | BW4: 2 | BY4: =VLOOKUP(M4,Consulta!$W$6:$AB$23,4,FALSE) -> 40 | BZ4: =VLOOKUP(M4,Consulta!$W$6:$AB$23,6,FALSE) -> 50 | CA4: =VLOOKUP(M4,Consulta!$AK$6:$AP$23,4,FALSE) -> 40 | CB4: =VLOOKUP(M4,Consulta!$AK$6:$AP$23,6,FALSE) -> 40 | CC4: =VLOOKUP(M4,Consulta!$AD$6:$AI$19,4,FALSE) -> 50 | CD4: =VLOOKUP(M4,Consulta!$AD$6:$AI$19,6,FALSE) -> 63 | CE4: =VLOOKUP(M4,Consulta!$AR$6:$AW$19,4,FALSE) -> 63 | CF4: =VLOOKUP(M4,Consulta!$AR$6:$AW$19,6,FALSE) -> 63
C5: Q.G.B.T. / Q_PS1 | D5: =SUM(D12:D20) -> 35.5 | E5: =0.344+5.8+0.3+15.35+2.1 -> 23.894 | F5: Trifásico | G5: Multicondutor | H5: 0.96 | I5: Cabo/Canalizações | J5: Cobre | K5: PVC | L5: 2 | M5: 6 | N5: E | O5: 13 | P5: =IF(K5="PVC",HLOOKUP(N5,$BA$3:$BI$104,BW5,FALSE),IF(OR(K5="XLPE",K5="EPR"),HLOOKUP(N5,$BJ$3:$BR$104,BW5,FALSE),IF(K5="Mineral",HLOOKUP(N5,$BS$3:$BV$104,BW5,FALSE),"N/A")))*L5 -> 86 | Q5: 5 | R5: 0.75 | S5: =IF(F5="Monofásico",(((D5*10^3)/H5)/230),(((D5*10^3)/H5)/(SQRT(3)*400))) -> 53.37483 | T5: =P5*R5 -> 64.5 | U5: Disjuntor | V5: 63 | W5: =IF(U5="C.C.Fusíveis",VLOOKUP(V5,Consulta!$L$5:$N$31,3,FALSE),VLOOKUP(V5,Consulta!$P$5:$R$34,3,FALSE)) -> 85 | X5: =CEILING(1.45*P5,1) -> 125 | Y5: =S5/T5 -> 0.82751674 | Z5: =IF(AND(S5<=V5,V5<=P5,W5<=X5),"Sim","Não") -> Sim | AA5: =$AA$4+SQRT($AB$4^2+$AC$4^2) -> 0.041154827 | AB5: =(IF(J5="Cobre",(1.25*0.0225),(1.25*0.036)))*((E5/M5)/L5) -> 0.056001562 | AC5: =(IF(M5<10,0,(0.00008)))*(E5) -> 0 | AD5: =$AF$4 -> 0.095511647 | AE5: =IF(F5="Trifásico",S5*(AB5*H5+AC5*SIN(ACOS(H5))),2*S5*(AB5*H5+AC5*SIN(ACOS(H5)))) -> 2.8695109 | AF5: =AD5+AE5 -> 2.9650225 | AG5: =AE5/230 -> 0.012476134 | AH5: =AF5/230 -> 0.012891402 | AI5: =IF(F5="Monofásico",(0.23/(SQRT((AB5^2)+(AC5^2))+AA5)),(0.4/(SQRT(3)*(SQRT((AB5^2)+(AC5^2))+AA5)))) -> 2.3769935 | AJ5: 3 | AK5: 0.1 | AL5: =IF(G5="Multicondutor",(IF(AND(J5="Cobre",K5="PVC"),115,IF(AND(J5="Cobre",K5="XLPE"),143,IF(AND(J5="Alumínio",K5="PVC"),76,IF(AND(J5="Alumínio",K5="XLPE"),94))))),(IF(AND(J5="Cobre",K5="PVC"),143,IF(AND(J5="Cobre",K5="XLPE"),176,IF(AND(J5="Alumínio",K5="PVC"),95,IF(AND(J5="Alumínio",K5="XLPE"),116)))))) -> 115 | AM5: =((AI5*1000)*SQRT(AK5))/AL5 -> 6.5362726 | AN5: =L5 -> 2 | AO5: × | AP5: [XV | AQ5: =IF(F5="Monofásico","3G",IF(AND(F5="Trifásico",M5<25),"5G","3×")) -> 5G | AR5: =M5 -> 6 | AS5: =IF(OR(AQ5="3G",AQ5="5G"),"","+2G") | AT5: =IF(OR(AQ5="3G",AQ5="5G"),"",VLOOKUP(AR5,Consulta!$T$5:$U$25,2,FALSE)) | AU5: mm2] | AV5: / | AW5: VD Ø | AX5: =IF(AND(F5="Monofásico",I5="Fio/Canalizações"),BY4,IF(AND(F5="Trifásico",I5="Fio/Canalizações"),BZ4,IF(AND(F5="Monofásico",I5="Cabo/Canalizações"),CA4,IF(AND(F5="Trifásico",I5="Cabo/Canalizações"),CB4,IF(AND(F5="Monofásico",I5="Fio/Colunas&Entradas"),CC4,IF(AND(F5="Trifásico",I5="Fio/Colunas&Entradas"),CD4,IF(AND(F5="Monofásico",I5="Cabo/Colunas&Entradas"),CE4,IF(AND(F5="Trifásico",I5="Cabo/Colunas&Entradas"),CF4)))))))) -> 40 | AY5: mm | BA5: =IF(AND(J5="Cobre",F5="Monofásico"),VLOOKUP(M5,'Iz''s'!$B$8:$E$23,2,FALSE),IF(AND(J5="Cobre",F5="Trifásico"),VLOOKUP(M5,'Iz''s'!$L$8:$O$23,2,FALSE),IF(AND(J5="Alumínio",F5="Monofásico"),VLOOKUP(M5,'Iz''s'!$B$25:$E$39,2,FALSE),IF(AND(J5="Alumínio",F5="Trifásico"),VLOOKUP(M5,'Iz''s'!$L$25:$O$39,2,FALSE))))) -> 31 | BB5: =IF(AND(J5="Cobre",F5="Monofásico"),VLOOKUP(M5,'Iz''s'!$CD$9:$CH$24,2,FALSE),IF(AND(J5="Cobre",F5="Trifásico"),VLOOKUP(M5,'Iz''s'!$CD$9:$CH$24,4,FALSE),IF(AND(J5="Alumínio",F5="Monofásico"),VLOOKUP(M5,'Iz''s'!$CD$26:$CH$40,2,FALSE),IF(AND(J5="Alumínio",F5="Trifásico"),VLOOKUP(M5,'Iz''s'!$CD$26:$CH$40,4,FALSE))))) -> 29 | BC5: =IF(AND(J5="Cobre",F5="Monofásico"),VLOOKUP(M5,'Iz''s'!$B$8:$E$23,3,FALSE),IF(AND(J5="Cobre",F5="Trifásico"),VLOOKUP(M5,'Iz''s'!$L$8:$O$23,3,FALSE),IF(AND(J5="Alumínio",F5="Monofásico"),VLOOKUP(M5,'Iz''s'!$B$25:$E$39,3,FALSE),IF(AND(J5="Alumínio",F5="Trifásico"),VLOOKUP(M5,'Iz''s'!$L$25:$O$39,3,FALSE))))) -> 36 | BD5: =IF(AND(J5="Cobre",F5="Monofásico"),VLOOKUP(M5,'Iz''s'!$CD$9:$CH$24,3,FALSE),IF(AND(J5="Cobre",F5="Trifásico"),VLOOKUP(M5,'Iz''s'!$CD$9:$CH$24,5,FALSE),IF(AND(J5="Alumínio",F5="Monofásico"),VLOOKUP(M5,'Iz''s'!$CD$26:$CH$40,3,FALSE),IF(AND(J5="Alumínio",F5="Trifásico"),VLOOKUP(M5,'Iz''s'!$CD$26:$CH$40,5,FALSE))))) -> 34 | BE5: =IF(AND(J5="Cobre",F5="Monofásico"),VLOOKUP(M5,'Iz''s'!$B$8:$E$23,4,FALSE),IF(AND(J5="Cobre",F5="Trifásico"),VLOOKUP(M5,'Iz''s'!$L$8:$O$23,4,FALSE),IF(AND(J5="Alumínio",F5="Monofásico"),VLOOKUP(M5,'Iz''s'!$B$25:$E$39,4,FALSE),IF(AND(J5="Alumínio",F5="Trifásico"),VLOOKUP(M5,'Iz''s'!$L$25:$O$39,4,FALSE))))) -> 41 | BF5: =IF(AND(J5="Cobre",F5="Monofásico"),VLOOKUP(M5,'Iz''s'!$CP$9:$CT$24,3,FALSE),IF(AND(J5="Cobre",F5="Trifásico"),VLOOKUP(M5,'Iz''s'!$CP$9:$CT$24,2,FALSE),IF(AND(J5="Alumínio",F5="Monofásico"),VLOOKUP(M5,'Iz''s'!$CP$26:$CT$37,3,FALSE),IF(AND(J5="Alumínio",F5="Trifásico"),VLOOKUP(M5,'Iz''s'!$CP$26:$CT$37,2,FALSE))))) -> 56 | BG5: =IF(AND(J5="Cobre",F5="Monofásico"),VLOOKUP(M5,'Iz''s'!$AT$10:$BA$28,2,FALSE),IF(AND(J5="Cobre",F5="Trifásico"),VLOOKUP(M5,'Iz''s'!$AT$10:$BA$28,3,FALSE),IF(AND(J5="Alumínio",F5="Monofásico"),VLOOKUP(M5,'Iz''s'!$BC$10:$BJ$27,2,FALSE),IF(AND(J5="Alumínio",F5="Trifásico"),VLOOKUP(M5,'Iz''s'!$BC$10:$BJ$27,3,FALSE))))) -> 43 | BH5: =IF(AND(J5="Cobre",F5="Monofásico"),VLOOKUP(M5,'Iz''s'!$AT$10:$BA$28,4,FALSE),IF(AND(J5="Cobre",F5="Trifásico"),VLOOKUP(M5,'Iz''s'!$AT$10:$BA$28,5,FALSE),IF(AND(J5="Alumínio",F5="Monofásico"),VLOOKUP(M5,'Iz''s'!$BC$10:$BJ$27,4,FALSE),IF(AND(J5="Alumínio",F5="Trifásico"),VLOOKUP(M5,'Iz''s'!$BC$10:$BJ$27,5,FALSE))))) -> --- | BI5: =IF(AND(J5="Cobre",F5="Monofásico"),"N/A",IF(AND(J5="Cobre",F5="Trifásico"),VLOOKUP(M5,'Iz''s'!$AT$10:$BA$28,8,FALSE),IF(AND(J5="Alumínio",F5="Monofásico"),"N/A",IF(AND(J5="Alumínio",F5="Trifásico"),VLOOKUP(M5,'Iz''s'!$BC$10:$BJ$27,8,FALSE))))) -> --- | BJ5: =IF(AND(J5="Cobre",F5="Monofásico"),VLOOKUP(M5,'Iz''s'!$G$8:$J$23,2,FALSE),IF(AND(J5="Cobre",F5="Trifásico"),VLOOKUP(M5,'Iz''s'!$Q$8:$T$23,2,FALSE),IF(AND(J5="Alumínio",F5="Monofásico"),VLOOKUP(M5,'Iz''s'!$G$25:$J$39,2,FALSE),IF(AND(J5="Alumínio",F5="Trifásico"),VLOOKUP(M5,'Iz''s'!$Q$25:$T$39,2,FALSE))))) -> 40 | BK5: =IF(AND(J5="Cobre",F5="Monofásico"),VLOOKUP(M5,'Iz''s'!$CJ$9:$CN$24,2,FALSE),IF(AND(J5="Cobre",F5="Trifásico"),VLOOKUP(M5,'Iz''s'!$CJ$9:$CN$24,4,FALSE),IF(AND(J5="Alumínio",F5="Monofásico"),VLOOKUP(M5,'Iz''s'!$CJ$26:$CN$40,2,FALSE),IF(AND(J5="Alumínio",F5="Trifásico"),VLOOKUP(M5,'Iz''s'!$CJ$26:$CN$40,4,FALSE))))) -> 38 | BL5: =IF(AND(J5="Cobre",F5="Monofásico"),VLOOKUP(M5,'Iz''s'!$G$8:$J$23,3,FALSE),IF(AND(J5="Cobre",F5="Trifásico"),VLOOKUP(M5,'Iz''s'!$Q$8:$T$23,3,FALSE),IF(AND(J5="Alumínio",F5="Monofásico"),VLOOKUP(M5,'Iz''s'!$G$25:$J$39,3,FALSE),IF(AND(J5="Alumínio",F5="Trifásico"),VLOOKUP(M5,'Iz''s'!$Q$25:$T$39,3,FALSE))))) -> 48 | BM5: =IF(AND(J5="Cobre",F5="Monofásico"),VLOOKUP(M5,'Iz''s'!$CJ$9:$CN$24,3,FALSE),IF(AND(J5="Cobre",F5="Trifásico"),VLOOKUP(M5,'Iz''s'!$CJ$9:$CN$24,5,FALSE),IF(AND(J5="Alumínio",F5="Monofásico"),VLOOKUP(M5,'Iz''s'!$CJ$26:$CN$40,3,FALSE),IF(AND(J5="Alumínio",F5="Trifásico"),VLOOKUP(M5,'Iz''s'!$CJ$26:$CN$40,5,FALSE))))) -> 44 | BN5: =IF(AND(J5="Cobre",F5="Monofásico"),VLOOKUP(M5,'Iz''s'!$G$8:$J$23,4,FALSE),IF(AND(J5="Cobre",F5="Trifásico"),VLOOKUP(M5,'Iz''s'!$Q$8:$T$23,4,FALSE),IF(AND(J5="Alumínio",F5="Monofásico"),VLOOKUP(M5,'Iz''s'!$G$25:$J$39,4,FALSE),IF(AND(J5="Alumínio",F5="Trifásico"),VLOOKUP(M5,'Iz''s'!$Q$25:$T$39,4,FALSE))))) -> 52 | BO5: =IF(AND(J5="Cobre",F5="Monofásico"),VLOOKUP(M5,'Iz''s'!$CP$9:$CT$24,5,FALSE),IF(AND(J5="Cobre",F5="Trifásico"),VLOOKUP(M5,'Iz''s'!$CP$9:$CT$24,4,FALSE),IF(AND(J5="Alumínio",F5="Monofásico"),VLOOKUP(M5,'Iz''s'!$CP$26:$CT$37,5,FALSE),IF(AND(J5="Alumínio",F5="Trifásico"),VLOOKUP(M5,'Iz''s'!$CP$26:$CT$37,4,FALSE))))) -> 66 | BP5: =IF(AND(J5="Cobre",F5="Monofásico"),VLOOKUP(M5,'Iz''s'!$BL$10:$BS$28,2,FALSE),IF(AND(J5="Cobre",F5="Trifásico"),VLOOKUP(M5,'Iz''s'!$BL$10:$BS$28,3,FALSE),IF(AND(J5="Alumínio",F5="Monofásico"),VLOOKUP(M5,'Iz''s'!$BU$10:$CB$27,2,FALSE),IF(AND(J5="Alumínio",F5="Trifásico"),VLOOKUP(M5,'Iz''s'!$BU$10:$CB$27,3,FALSE))))) -> 54 | BQ5: =IF(AND(J5="Cobre",F5="Monofásico"),VLOOKUP(M5,'Iz''s'!$BL$10:$BS$28,4,FALSE),IF(AND(J5="Cobre",F5="Trifásico"),VLOOKUP(M5,'Iz''s'!$BL$10:$BS$28,5,FALSE),IF(AND(J5="Alumínio",F5="Monofásico"),VLOOKUP(M5,'Iz''s'!$BU$10:$CB$27,4,FALSE),IF(AND(J5="Alumínio",F5="Trifásico"),VLOOKUP(M5,'Iz''s'!$BU$10:$CB$27,5,FALSE))))) -> --- | BR5: =IF(AND(J5="Cobre",F5="Monofásico"),"N/A",IF(AND(J5="Cobre",F5="Trifásico"),VLOOKUP(M5,'Iz''s'!$BL$10:$BS$28,8,FALSE),IF(AND(J5="Alumínio",F5="Monofásico"),"N/A",IF(AND(J5="Alumínio",F5="Trifásico"),VLOOKUP(M5,'Iz''s'!$BU$10:$CB$27,8,FALSE))))) -> --- | BS5: =IF(AND(J5="Cobre",F5="Monofásico"),VLOOKUP(M5,'Iz''s'!$V$14:$Y$28,2,FALSE),IF(AND(J5="Cobre",F5="Trifásico"),VLOOKUP(M5,'Iz''s'!$V$14:$Y$28,3,FALSE),IF(AND(J5="Alumínio",F5="Monofásico"),VLOOKUP(M5,"N/A",4,FALSE),IF(AND(J5="Alumínio",F5="Trifásico"),VLOOKUP(M5,"N/A",4,FALSE))))) -> 48 | BT5: =IF(AND(J5="Cobre",F5="Monofásico"),VLOOKUP(M5,'Iz''s'!$AF$15:$AK$29,2,FALSE),IF(AND(J5="Cobre",F5="Trifásico"),VLOOKUP(M5,'Iz''s'!$AF$15:$AK$29,3,FALSE),IF(AND(J5="Alumínio",F5="Monofásico"),"N/A",IF(AND(J5="Alumínio",F5="Trifásico"),"N/A")))) -> 51 | BU5: =IF(AND(J5="Cobre",F5="Monofásico"),VLOOKUP(M5,'Iz''s'!$AF$15:$AK$29,2,FALSE),IF(AND(J5="Cobre",F5="Trifásico"),VLOOKUP(M5,'Iz''s'!$AF$15:$AK$29,3,FALSE),IF(AND(J5="Alumínio",F5="Monofásico"),"N/A",IF(AND(J5="Alumínio",F5="Trifásico"),"N/A")))) -> 51 | BV5: =IF(AND(J5="Cobre",F5="Monofásico"),"N/A",IF(AND(J5="Cobre",F5="Trifásico"),VLOOKUP(M5,'Iz''s'!$AF$15:$AK$29,6,FALSE),IF(AND(J5="Alumínio",F5="Monofásico"),"N/A",IF(AND(J5="Alumínio",F5="Trifásico"),"N/A")))) -> 71 | BW5: 3 | BY5: =VLOOKUP(M5,Consulta!$W$6:$AB$23,4,FALSE) -> 20 | BZ5: =VLOOKUP(M5,Consulta!$W$6:$AB$23,6,FALSE) -> 25 | CA5: =VLOOKUP(M5,Consulta!$AK$6:$AP$23,4,FALSE) -> 25 | CB5: =VLOOKUP(M5,Consulta!$AK$6:$AP$23,6,FALSE) -> 32 | CC5: =VLOOKUP(M5,Consulta!$AD$6:$AI$19,4,FALSE) -> #N/A | CD5: =VLOOKUP(M5,Consulta!$AD$6:$AI$19,6,FALSE) -> #N/A | CE5: =VLOOKUP(M5,Consulta!$AR$6:$AW$19,4,FALSE) -> #N/A | CF5: =VLOOKUP(M5,Consulta!$AR$6:$AW$19,6,FALSE) -> #N/A
C6: Q.G.B.T. / Q_PS2 | D6: =SUM(D21:D34) -> 43.36 | E6: =0.344+5.8+0.3+15.35+2.1+2 -> 25.894 | F6: Trifásico | G6: Multicondutor | H6: 0.96 | I6: Cabo/Canalizações | J6: Cobre | K6: PVC | L6: 2 | M6: 10 | N6: E | O6: 13 | P6: =IF(K6="PVC",HLOOKUP(N6,$BA$3:$BI$104,BW6,FALSE),IF(OR(K6="XLPE",K6="EPR"),HLOOKUP(N6,$BJ$3:$BR$104,BW6,FALSE),IF(K6="Mineral",HLOOKUP(N6,$BS$3:$BV$104,BW6,FALSE),"N/A")))*L6 -> 120 | Q6: 5 | R6: 0.75 | S6: =IF(F6="Monofásico",(((D6*10^3)/H6)/230),(((D6*10^3)/H6)/(SQRT(3)*400))) -> 65.192468 | T6: =P6*R6 -> 90 | U6: Disjuntor | V6: 80 | W6: =IF(U6="C.C.Fusíveis",VLOOKUP(V6,Consulta!$L$5:$N$31,3,FALSE),VLOOKUP(V6,Consulta!$P$5:$R$34,3,FALSE)) -> 108 | X6: =CEILING(1.45*P6,1) -> 174 | Y6: =S6/T6 -> 0.72436075 | Z6: =IF(AND(S6<=V6,V6<=P6,W6<=X6),"Sim","Não") -> Sim | AA6: =$AA$4+SQRT($AB$4^2+$AC$4^2) -> 0.041154827 | AB6: =(IF(J6="Cobre",(1.25*0.0225),(1.25*0.036)))*((E6/M6)/L6) -> 0.036413437 | AC6: =(IF(M6<10,0,(0.00008)))*(E6) -> 0.00207152 | AD6: =$AF$4 -> 0.095511647 | AE6: =IF(F6="Trifásico",S6*(AB6*H6+AC6*SIN(ACOS(H6))),2*S6*(AB6*H6+AC6*SIN(ACOS(H6)))) -> 2.3167399 | AF6: =AD6+AE6 -> 2.4122515 | AG6: =AE6/230 -> 0.010072782 | AH6: =AF6/230 -> 0.01048805 | AI6: =IF(F6="Monofásico",(0.23/(SQRT((AB6^2)+(AC6^2))+AA6)),(0.4/(SQRT(3)*(SQRT((AB6^2)+(AC6^2))+AA6)))) -> 2.9749918 | AJ6: 3 | AK6: 0.1 | AL6: =IF(G6="Multicondutor",(IF(AND(J6="Cobre",K6="PVC"),115,IF(AND(J6="Cobre",K6="XLPE"),143,IF(AND(J6="Alumínio",K6="PVC"),76,IF(AND(J6="Alumínio",K6="XLPE"),94))))),(IF(AND(J6="Cobre",K6="PVC"),143,IF(AND(J6="Cobre",K6="XLPE"),176,IF(AND(J6="Alumínio",K6="PVC"),95,IF(AND(J6="Alumínio",K6="XLPE"),116)))))) -> 115 | AM6: =((AI6*1000)*SQRT(AK6))/AL6 -> 8.1806523 | AN6: =L6 -> 2 | AO6: × | AP6: [XV | AQ6: =IF(F6="Monofásico","3G",IF(AND(F6="Trifásico",M6<25),"5G","3×")) -> 5G | AR6: =M6 -> 10 | AS6: =IF(OR(AQ6="3G",AQ6="5G"),"","+2G") | AT6: =IF(OR(AQ6="3G",AQ6="5G"),"",VLOOKUP(AR6,Consulta!$T$5:$U$25,2,FALSE)) | AU6: mm2] | AV6: / | AW6: VD Ø | AX6: =IF(AND(F6="Monofásico",I6="Fio/Canalizações"),BY5,IF(AND(F6="Trifásico",I6="Fio/Canalizações"),BZ5,IF(AND(F6="Monofásico",I6="Cabo/Canalizações"),CA5,IF(AND(F6="Trifásico",I6="Cabo/Canalizações"),CB5,IF(AND(F6="Monofásico",I6="Fio/Colunas&Entradas"),CC5,IF(AND(F6="Trifásico",I6="Fio/Colunas&Entradas"),CD5,IF(AND(F6="Monofásico",I6="Cabo/Colunas&Entradas"),CE5,IF(AND(F6="Trifásico",I6="Cabo/Colunas&Entradas"),CF5)))))))) -> 32 | AY6: mm | BA6: =IF(AND(J6="Cobre",F6="Monofásico"),VLOOKUP(M6,'Iz''s'!$B$8:$E$23,2,FALSE),IF(AND(J6="Cobre",F6="Trifásico"),VLOOKUP(M6,'Iz''s'!$L$8:$O$23,2,FALSE),IF(AND(J6="Alumínio",F6="Monofásico"),VLOOKUP(M6,'Iz''s'!$B$25:$E$39,2,FALSE),IF(AND(J6="Alumínio",F6="Trifásico"),VLOOKUP(M6,'Iz''s'!$L$25:$O$39,2,FALSE))))) -> 42 | BB6: =IF(AND(J6="Cobre",F6="Monofásico"),VLOOKUP(M6,'Iz''s'!$CD$9:$CH$24,2,FALSE),IF(AND(J6="Cobre",F6="Trifásico"),VLOOKUP(M6,'Iz''s'!$CD$9:$CH$24,4,FALSE),IF(AND(J6="Alumínio",F6="Monofásico"),VLOOKUP(M6,'Iz''s'!$CD$26:$CH$40,2,FALSE),IF(AND(J6="Alumínio",F6="Trifásico"),VLOOKUP(M6,'Iz''s'!$CD$26:$CH$40,4,FALSE))))) -> 39 | BC6: =IF(AND(J6="Cobre",F6="Monofásico"),VLOOKUP(M6,'Iz''s'!$B$8:$E$23,3,FALSE),IF(AND(J6="Cobre",F6="Trifásico"),VLOOKUP(M6,'Iz''s'!$L$8:$O$23,3,FALSE),IF(AND(J6="Alumínio",F6="Monofásico"),VLOOKUP(M6,'Iz''s'!$B$25:$E$39,3,FALSE),IF(AND(J6="Alumínio",F6="Trifásico"),VLOOKUP(M6,'Iz''s'!$L$25:$O$39,3,FALSE))))) -> 50 | BD6: =IF(AND(J6="Cobre",F6="Monofásico"),VLOOKUP(M6,'Iz''s'!$CD$9:$CH$24,3,FALSE),IF(AND(J6="Cobre",F6="Trifásico"),VLOOKUP(M6,'Iz''s'!$CD$9:$CH$24,5,FALSE),IF(AND(J6="Alumínio",F6="Monofásico"),VLOOKUP(M6,'Iz''s'!$CD$26:$CH$40,3,FALSE),IF(AND(J6="Alumínio",F6="Trifásico"),VLOOKUP(M6,'Iz''s'!$CD$26:$CH$40,5,FALSE))))) -> 46 | BE6: =IF(AND(J6="Cobre",F6="Monofásico"),VLOOKUP(M6,'Iz''s'!$B$8:$E$23,4,FALSE),IF(AND(J6="Cobre",F6="Trifásico"),VLOOKUP(M6,'Iz''s'!$L$8:$O$23,4,FALSE),IF(AND(J6="Alumínio",F6="Monofásico"),VLOOKUP(M6,'Iz''s'!$B$25:$E$39,4,FALSE),IF(AND(J6="Alumínio",F6="Trifásico"),VLOOKUP(M6,'Iz''s'!$L$25:$O$39,4,FALSE))))) -> 57 | BF6: =IF(AND(J6="Cobre",F6="Monofásico"),VLOOKUP(M6,'Iz''s'!$CP$9:$CT$24,3,FALSE),IF(AND(J6="Cobre",F6="Trifásico"),VLOOKUP(M6,'Iz''s'!$CP$9:$CT$24,2,FALSE),IF(AND(J6="Alumínio",F6="Monofásico"),VLOOKUP(M6,'Iz''s'!$CP$26:$CT$37,3,FALSE),IF(AND(J6="Alumínio",F6="Trifásico"),VLOOKUP(M6,'Iz''s'!$CP$26:$CT$37,2,FALSE))))) -> 74 | BG6: =IF(AND(J6="Cobre",F6="Monofásico"),VLOOKUP(M6,'Iz''s'!$AT$10:$BA$28,2,FALSE),IF(AND(J6="Cobre",F6="Trifásico"),VLOOKUP(M6,'Iz''s'!$AT$10:$BA$28,3,FALSE),IF(AND(J6="Alumínio",F6="Monofásico"),VLOOKUP(M6,'Iz''s'!$BC$10:$BJ$27,2,FALSE),IF(AND(J6="Alumínio",F6="Trifásico"),VLOOKUP(M6,'Iz''s'!$BC$10:$BJ$27,3,FALSE))))) -> 60 | BH6: =IF(AND(J6="Cobre",F6="Monofásico"),VLOOKUP(M6,'Iz''s'!$AT$10:$BA$28,4,FALSE),IF(AND(J6="Cobre",F6="Trifásico"),VLOOKUP(M6,'Iz''s'!$AT$10:$BA$28,5,FALSE),IF(AND(J6="Alumínio",F6="Monofásico"),VLOOKUP(M6,'Iz''s'!$BC$10:$BJ$27,4,FALSE),IF(AND(J6="Alumínio",F6="Trifásico"),VLOOKUP(M6,'Iz''s'!$BC$10:$BJ$27,5,FALSE))))) -> --- | BI6: =IF(AND(J6="Cobre",F6="Monofásico"),"N/A",IF(AND(J6="Cobre",F6="Trifásico"),VLOOKUP(M6,'Iz''s'!$AT$10:$BA$28,8,FALSE),IF(AND(J6="Alumínio",F6="Monofásico"),"N/A",IF(AND(J6="Alumínio",F6="Trifásico"),VLOOKUP(M6,'Iz''s'!$BC$10:$BJ$27,8,FALSE))))) -> --- | BJ6: =IF(AND(J6="Cobre",F6="Monofásico"),VLOOKUP(M6,'Iz''s'!$G$8:$J$23,2,FALSE),IF(AND(J6="Cobre",F6="Trifásico"),VLOOKUP(M6,'Iz''s'!$Q$8:$T$23,2,FALSE),IF(AND(J6="Alumínio",F6="Monofásico"),VLOOKUP(M6,'Iz''s'!$G$25:$J$39,2,FALSE),IF(AND(J6="Alumínio",F6="Trifásico"),VLOOKUP(M6,'Iz''s'!$Q$25:$T$39,2,FALSE))))) -> 54 | BK6: =IF(AND(J6="Cobre",F6="Monofásico"),VLOOKUP(M6,'Iz''s'!$CJ$9:$CN$24,2,FALSE),IF(AND(J6="Cobre",F6="Trifásico"),VLOOKUP(M6,'Iz''s'!$CJ$9:$CN$24,4,FALSE),IF(AND(J6="Alumínio",F6="Monofásico"),VLOOKUP(M6,'Iz''s'!$CJ$26:$CN$40,2,FALSE),IF(AND(J6="Alumínio",F6="Trifásico"),VLOOKUP(M6,'Iz''s'!$CJ$26:$CN$40,4,FALSE))))) -> 51 | BL6: =IF(AND(J6="Cobre",F6="Monofásico"),VLOOKUP(M6,'Iz''s'!$G$8:$J$23,3,FALSE),IF(AND(J6="Cobre",F6="Trifásico"),VLOOKUP(M6,'Iz''s'!$Q$8:$T$23,3,FALSE),IF(AND(J6="Alumínio",F6="Monofásico"),VLOOKUP(M6,'Iz''s'!$G$25:$J$39,3,FALSE),IF(AND(J6="Alumínio",F6="Trifásico"),VLOOKUP(M6,'Iz''s'!$Q$25:$T$39,3,FALSE))))) -> 66 | BM6: =IF(AND(J6="Cobre",F6="Monofásico"),VLOOKUP(M6,'Iz''s'!$CJ$9:$CN$24,3,FALSE),IF(AND(J6="Cobre",F6="Trifásico"),VLOOKUP(M6,'Iz''s'!$CJ$9:$CN$24,5,FALSE),IF(AND(J6="Alumínio",F6="Monofásico"),VLOOKUP(M6,'Iz''s'!$CJ$26:$CN$40,3,FALSE),IF(AND(J6="Alumínio",F6="Trifásico"),VLOOKUP(M6,'Iz''s'!$CJ$26:$CN$40,5,FALSE))))) -> 60 | BN6: =IF(AND(J6="Cobre",F6="Monofásico"),VLOOKUP(M6,'Iz''s'!$G$8:$J$23,4,FALSE),IF(AND(J6="Cobre",F6="Trifásico"),VLOOKUP(M6,'Iz''s'!$Q$8:$T$23,4,FALSE),IF(AND(J6="Alumínio",F6="Monofásico"),VLOOKUP(M6,'Iz''s'!$G$25:$J$39,4,FALSE),IF(AND(J6="Alumínio",F6="Trifásico"),VLOOKUP(M6,'Iz''s'!$Q$25:$T$39,4,FALSE))))) -> 71 | BO6: =IF(AND(J6="Cobre",F6="Monofásico"),VLOOKUP(M6,'Iz''s'!$CP$9:$CT$24,5,FALSE),IF(AND(J6="Cobre",F6="Trifásico"),VLOOKUP(M6,'Iz''s'!$CP$9:$CT$24,4,FALSE),IF(AND(J6="Alumínio",F6="Monofásico"),VLOOKUP(M6,'Iz''s'!$CP$26:$CT$37,5,FALSE),IF(AND(J6="Alumínio",F6="Trifásico"),VLOOKUP(M6,'Iz''s'!$CP$26:$CT$37,4,FALSE))))) -> 87 | BP6: =IF(AND(J6="Cobre",F6="Monofásico"),VLOOKUP(M6,'Iz''s'!$BL$10:$BS$28,2,FALSE),IF(AND(J6="Cobre",F6="Trifásico"),VLOOKUP(M6,'Iz''s'!$BL$10:$BS$28,3,FALSE),IF(AND(J6="Alumínio",F6="Monofásico"),VLOOKUP(M6,'Iz''s'!$BU$10:$CB$27,2,FALSE),IF(AND(J6="Alumínio",F6="Trifásico"),VLOOKUP(M6,'Iz''s'!$BU$10:$CB$27,3,FALSE))))) -> 75 | BQ6: =IF(AND(J6="Cobre",F6="Monofásico"),VLOOKUP(M6,'Iz''s'!$BL$10:$BS$28,4,FALSE),IF(AND(J6="Cobre",F6="Trifásico"),VLOOKUP(M6,'Iz''s'!$BL$10:$BS$28,5,FALSE),IF(AND(J6="Alumínio",F6="Monofásico"),VLOOKUP(M6,'Iz''s'!$BU$10:$CB$27,4,FALSE),IF(AND(J6="Alumínio",F6="Trifásico"),VLOOKUP(M6,'Iz''s'!$BU$10:$CB$27,5,FALSE))))) -> --- | BR6: =IF(AND(J6="Cobre",F6="Monofásico"),"N/A",IF(AND(J6="Cobre",F6="Trifásico"),VLOOKUP(M6,'Iz''s'!$BL$10:$BS$28,8,FALSE),IF(AND(J6="Alumínio",F6="Monofásico"),"N/A",IF(AND(J6="Alumínio",F6="Trifásico"),VLOOKUP(M6,'Iz''s'!$BU$10:$CB$27,8,FALSE))))) -> --- | BS6: =IF(AND(J6="Cobre",F6="Monofásico"),VLOOKUP(M6,'Iz''s'!$V$14:$Y$28,2,FALSE),IF(AND(J6="Cobre",F6="Trifásico"),VLOOKUP(M6,'Iz''s'!$V$14:$Y$28,3,FALSE),IF(AND(J6="Alumínio",F6="Monofásico"),VLOOKUP(M6,"N/A",4,FALSE),IF(AND(J6="Alumínio",F6="Trifásico"),VLOOKUP(M6,"N/A",4,FALSE))))) -> 65 | BT6: =IF(AND(J6="Cobre",F6="Monofásico"),VLOOKUP(M6,'Iz''s'!$AF$15:$AK$29,2,FALSE),IF(AND(J6="Cobre",F6="Trifásico"),VLOOKUP(M6,'Iz''s'!$AF$15:$AK$29,3,FALSE),IF(AND(J6="Alumínio",F6="Monofásico"),"N/A",IF(AND(J6="Alumínio",F6="Trifásico"),"N/A")))) -> 69 | BU6: =IF(AND(J6="Cobre",F6="Monofásico"),VLOOKUP(M6,'Iz''s'!$AF$15:$AK$29,2,FALSE),IF(AND(J6="Cobre",F6="Trifásico"),VLOOKUP(M6,'Iz''s'!$AF$15:$AK$29,3,FALSE),IF(AND(J6="Alumínio",F6="Monofásico"),"N/A",IF(AND(J6="Alumínio",F6="Trifásico"),"N/A")))) -> 69 | BV6: =IF(AND(J6="Cobre",F6="Monofásico"),"N/A",IF(AND(J6="Cobre",F6="Trifásico"),VLOOKUP(M6,'Iz''s'!$AF$15:$AK$29,6,FALSE),IF(AND(J6="Alumínio",F6="Monofásico"),"N/A",IF(AND(J6="Alumínio",F6="Trifásico"),"N/A")))) -> 95 | BW6: 4 | BY6: =VLOOKUP(M6,Consulta!$W$6:$AB$23,4,FALSE) -> 25 | BZ6: =VLOOKUP(M6,Consulta!$W$6:$AB$23,6,FALSE) -> 32 | CA6: =VLOOKUP(M6,Consulta!$AK$6:$AP$23,4,FALSE) -> 32 | CB6: =VLOOKUP(M6,Consulta!$AK$6:$AP$23,6,FALSE) -> 32 | CC6: =VLOOKUP(M6,Consulta!$AD$6:$AI$19,4,FALSE) -> 32 | CD6: =VLOOKUP(M6,Consulta!$AD$6:$AI$19,6,FALSE) -> 40 | CE6: =VLOOKUP(M6,Consulta!$AR$6:$AW$19,4,FALSE) -> 50 | CF6: =VLOOKUP(M6,Consulta!$AR$6:$AW$19,6,FALSE) -> 50
C7: Q.G.B.T. / Q_PS3 | D7: =SUM(D35:D49) -> 31.803 | E7: =0.6516+0.736 -> 1.3876 | F7: Trifásico | G7: Multicondutor | H7: 0.96 | I7: Cabo/Canalizações | J7: Cobre | K7: PVC | L7: 2 | M7: 6 | N7: E | O7: 13 | P7: =IF(K7="PVC",HLOOKUP(N7,$BA$3:$BI$104,BW7,FALSE),IF(OR(K7="XLPE",K7="EPR"),HLOOKUP(N7,$BJ$3:$BR$104,BW7,FALSE),IF(K7="Mineral",HLOOKUP(N7,$BS$3:$BV$104,BW7,FALSE),"N/A")))*L7 -> 86 | Q7: 5 | R7: 0.75 | S7: =IF(F7="Monofásico",(((D7*10^3)/H7)/230),(((D7*10^3)/H7)/(SQRT(3)*400))) -> 47.81633 | T7: =P7*R7 -> 64.5 | U7: Disjuntor | V7: 63 | W7: =IF(U7="C.C.Fusíveis",VLOOKUP(V7,Consulta!$L$5:$N$31,3,FALSE),VLOOKUP(V7,Consulta!$P$5:$R$34,3,FALSE)) -> 85 | X7: =CEILING(1.45*P7,1) -> 125 | Y7: =S7/T7 -> 0.74133845 | Z7: =IF(AND(S7<=V7,V7<=P7,W7<=X7),"Sim","Não") -> Sim | AA7: =$AA$4+SQRT($AB$4^2+$AC$4^2) -> 0.041154827 | AB7: =(IF(J7="Cobre",(1.25*0.0225),(1.25*0.036)))*((E7/M7)/L7) -> 0.0032521875 | AC7: =(IF(M7<10,0,(0.00008)))*(E7) -> 0 | AD7: =$AF$4 -> 0.095511647 | AE7: =IF(F7="Trifásico",S7*(AB7*H7+AC7*SIN(ACOS(H7))),2*S7*(AB7*H7+AC7*SIN(ACOS(H7)))) -> 0.14928736 | AF7: =AD7+AE7 -> 0.24479901 | AG7: =AE7/230 -> 0.00064907549 | AH7: =AF7/230 -> 0.0010643435 | AI7: =IF(F7="Monofásico",(0.23/(SQRT((AB7^2)+(AC7^2))+AA7)),(0.4/(SQRT(3)*(SQRT((AB7^2)+(AC7^2))+AA7)))) -> 5.2005322 | AJ7: 3 | AK7: 0.1 | AL7: =IF(G7="Multicondutor",(IF(AND(J7="Cobre",K7="PVC"),115,IF(AND(J7="Cobre",K7="XLPE"),143,IF(AND(J7="Alumínio",K7="PVC"),76,IF(AND(J7="Alumínio",K7="XLPE"),94))))),(IF(AND(J7="Cobre",K7="PVC"),143,IF(AND(J7="Cobre",K7="XLPE"),176,IF(AND(J7="Alumínio",K7="PVC"),95,IF(AND(J7="Alumínio",K7="XLPE"),116)))))) -> 115 | AM7: =((AI7*1000)*SQRT(AK7))/AL7 -> 14.300458 | AN7: =L7 -> 2 | AO7: × | AP7: [XV | AQ7: =IF(F7="Monofásico","3G",IF(AND(F7="Trifásico",M7<25),"5G","3×")) -> 5G | AR7: =M7 -> 6 | AS7: =IF(OR(AQ7="3G",AQ7="5G"),"","+2G") | AT7: =IF(OR(AQ7="3G",AQ7="5G"),"",VLOOKUP(AR7,Consulta!$T$5:$U$25,2,FALSE)) | AU7: mm2] | AV7: / | AW7: VD Ø | AX7: =IF(AND(F7="Monofásico",I7="Fio/Canalizações"),BY6,IF(AND(F7="Trifásico",I7="Fio/Canalizações"),BZ6,IF(AND(F7="Monofásico",I7="Cabo/Canalizações"),CA6,IF(AND(F7="Trifásico",I7="Cabo/Canalizações"),CB6,IF(AND(F7="Monofásico",I7="Fio/Colunas&Entradas"),CC6,IF(AND(F7="Trifásico",I7="Fio/Colunas&Entradas"),CD6,IF(AND(F7="Monofásico",I7="Cabo/Colunas&Entradas"),CE6,IF(AND(F7="Trifásico",I7="Cabo/Colunas&Entradas"),CF6)))))))) -> 32 | AY7: mm | BA7: =IF(AND(J7="Cobre",F7="Monofásico"),VLOOKUP(M7,'Iz''s'!$B$8:$E$23,2,FALSE),IF(AND(J7="Cobre",F7="Trifásico"),VLOOKUP(M7,'Iz''s'!$L$8:$O$23,2,FALSE),IF(AND(J7="Alumínio",F7="Monofásico"),VLOOKUP(M7,'Iz''s'!$B$25:$E$39,2,FALSE),IF(AND(J7="Alumínio",F7="Trifásico"),VLOOKUP(M7,'Iz''s'!$L$25:$O$39,2,FALSE))))) -> 31 | BB7: =IF(AND(J7="Cobre",F7="Monofásico"),VLOOKUP(M7,'Iz''s'!$CD$9:$CH$24,2,FALSE),IF(AND(J7="Cobre",F7="Trifásico"),VLOOKUP(M7,'Iz''s'!$CD$9:$CH$24,4,FALSE),IF(AND(J7="Alumínio",F7="Monofásico"),VLOOKUP(M7,'Iz''s'!$CD$26:$CH$40,2,FALSE),IF(AND(J7="Alumínio",F7="Trifásico"),VLOOKUP(M7,'Iz''s'!$CD$26:$CH$40,4,FALSE))))) -> 29 | BC7: =IF(AND(J7="Cobre",F7="Monofásico"),VLOOKUP(M7,'Iz''s'!$B$8:$E$23,3,FALSE),IF(AND(J7="Cobre",F7="Trifásico"),VLOOKUP(M7,'Iz''s'!$L$8:$O$23,3,FALSE),IF(AND(J7="Alumínio",F7="Monofásico"),VLOOKUP(M7,'Iz''s'!$B$25:$E$39,3,FALSE),IF(AND(J7="Alumínio",F7="Trifásico"),VLOOKUP(M7,'Iz''s'!$L$25:$O$39,3,FALSE))))) -> 36 | BD7: =IF(AND(J7="Cobre",F7="Monofásico"),VLOOKUP(M7,'Iz''s'!$CD$9:$CH$24,3,FALSE),IF(AND(J7="Cobre",F7="Trifásico"),VLOOKUP(M7,'Iz''s'!$CD$9:$CH$24,5,FALSE),IF(AND(J7="Alumínio",F7="Monofásico"),VLOOKUP(M7,'Iz''s'!$CD$26:$CH$40,3,FALSE),IF(AND(J7="Alumínio",F7="Trifásico"),VLOOKUP(M7,'Iz''s'!$CD$26:$CH$40,5,FALSE))))) -> 34 | BE7: =IF(AND(J7="Cobre",F7="Monofásico"),VLOOKUP(M7,'Iz''s'!$B$8:$E$23,4,FALSE),IF(AND(J7="Cobre",F7="Trifásico"),VLOOKUP(M7,'Iz''s'!$L$8:$O$23,4,FALSE),IF(AND(J7="Alumínio",F7="Monofásico"),VLOOKUP(M7,'Iz''s'!$B$25:$E$39,4,FALSE),IF(AND(J7="Alumínio",F7="Trifásico"),VLOOKUP(M7,'Iz''s'!$L$25:$O$39,4,FALSE))))) -> 41 | BF7: =IF(AND(J7="Cobre",F7="Monofásico"),VLOOKUP(M7,'Iz''s'!$CP$9:$CT$24,3,FALSE),IF(AND(J7="Cobre",F7="Trifásico"),VLOOKUP(M7,'Iz''s'!$CP$9:$CT$24,2,FALSE),IF(AND(J7="Alumínio",F7="Monofásico"),VLOOKUP(M7,'Iz''s'!$CP$26:$CT$37,3,FALSE),IF(AND(J7="Alumínio",F7="Trifásico"),VLOOKUP(M7,'Iz''s'!$CP$26:$CT$37,2,FALSE))))) -> 56 | BG7: =IF(AND(J7="Cobre",F7="Monofásico"),VLOOKUP(M7,'Iz''s'!$AT$10:$BA$28,2,FALSE),IF(AND(J7="Cobre",F7="Trifásico"),VLOOKUP(M7,'Iz''s'!$AT$10:$BA$28,3,FALSE),IF(AND(J7="Alumínio",F7="Monofásico"),VLOOKUP(M7,'Iz''s'!$BC$10:$BJ$27,2,FALSE),IF(AND(J7="Alumínio",F7="Trifásico"),VLOOKUP(M7,'Iz''s'!$BC$10:$BJ$27,3,FALSE))))) -> 43 | BH7: =IF(AND(J7="Cobre",F7="Monofásico"),VLOOKUP(M7,'Iz''s'!$AT$10:$BA$28,4,FALSE),IF(AND(J7="Cobre",F7="Trifásico"),VLOOKUP(M7,'Iz''s'!$AT$10:$BA$28,5,FALSE),IF(AND(J7="Alumínio",F7="Monofásico"),VLOOKUP(M7,'Iz''s'!$BC$10:$BJ$27,4,FALSE),IF(AND(J7="Alumínio",F7="Trifásico"),VLOOKUP(M7,'Iz''s'!$BC$10:$BJ$27,5,FALSE))))) -> --- | BI7: =IF(AND(J7="Cobre",F7="Monofásico"),"N/A",IF(AND(J7="Cobre",F7="Trifásico"),VLOOKUP(M7,'Iz''s'!$AT$10:$BA$28,8,FALSE),IF(AND(J7="Alumínio",F7="Monofásico"),"N/A",IF(AND(J7="Alumínio",F7="Trifásico"),VLOOKUP(M7,'Iz''s'!$BC$10:$BJ$27,8,FALSE))))) -> --- | BJ7: =IF(AND(J7="Cobre",F7="Monofásico"),VLOOKUP(M7,'Iz''s'!$G$8:$J$23,2,FALSE),IF(AND(J7="Cobre",F7="Trifásico"),VLOOKUP(M7,'Iz''s'!$Q$8:$T$23,2,FALSE),IF(AND(J7="Alumínio",F7="Monofásico"),VLOOKUP(M7,'Iz''s'!$G$25:$J$39,2,FALSE),IF(AND(J7="Alumínio",F7="Trifásico"),VLOOKUP(M7,'Iz''s'!$Q$25:$T$39,2,FALSE))))) -> 40 | BK7: =IF(AND(J7="Cobre",F7="Monofásico"),VLOOKUP(M7,'Iz''s'!$CJ$9:$CN$24,2,FALSE),IF(AND(J7="Cobre",F7="Trifásico"),VLOOKUP(M7,'Iz''s'!$CJ$9:$CN$24,4,FALSE),IF(AND(J7="Alumínio",F7="Monofásico"),VLOOKUP(M7,'Iz''s'!$CJ$26:$CN$40,2,FALSE),IF(AND(J7="Alumínio",F7="Trifásico"),VLOOKUP(M7,'Iz''s'!$CJ$26:$CN$40,4,FALSE))))) -> 38 | BL7: =IF(AND(J7="Cobre",F7="Monofásico"),VLOOKUP(M7,'Iz''s'!$G$8:$J$23,3,FALSE),IF(AND(J7="Cobre",F7="Trifásico"),VLOOKUP(M7,'Iz''s'!$Q$8:$T$23,3,FALSE),IF(AND(J7="Alumínio",F7="Monofásico"),VLOOKUP(M7,'Iz''s'!$G$25:$J$39,3,FALSE),IF(AND(J7="Alumínio",F7="Trifásico"),VLOOKUP(M7,'Iz''s'!$Q$25:$T$39,3,FALSE))))) -> 48 | BM7: =IF(AND(J7="Cobre",F7="Monofásico"),VLOOKUP(M7,'Iz''s'!$CJ$9:$CN$24,3,FALSE),IF(AND(J7="Cobre",F7="Trifásico"),VLOOKUP(M7,'Iz''s'!$CJ$9:$CN$24,5,FALSE),IF(AND(J7="Alumínio",F7="Monofásico"),VLOOKUP(M7,'Iz''s'!$CJ$26:$CN$40,3,FALSE),IF(AND(J7="Alumínio",F7="Trifásico"),VLOOKUP(M7,'Iz''s'!$CJ$26:$CN$40,5,FALSE))))) -> 44 | BN7: =IF(AND(J7="Cobre",F7="Monofásico"),VLOOKUP(M7,'Iz''s'!$G$8:$J$23,4,FALSE),IF(AND(J7="Cobre",F7="Trifásico"),VLOOKUP(M7,'Iz''s'!$Q$8:$T$23,4,FALSE),IF(AND(J7="Alumínio",F7="Monofásico"),VLOOKUP(M7,'Iz''s'!$G$25:$J$39,4,FALSE),IF(AND(J7="Alumínio",F7="Trifásico"),VLOOKUP(M7,'Iz''s'!$Q$25:$T$39,4,FALSE))))) -> 52 | BO7: =IF(AND(J7="Cobre",F7="Monofásico"),VLOOKUP(M7,'Iz''s'!$CP$9:$CT$24,5,FALSE),IF(AND(J7="Cobre",F7="Trifásico"),VLOOKUP(M7,'Iz''s'!$CP$9:$CT$24,4,FALSE),IF(AND(J7="Alumínio",F7="Monofásico"),VLOOKUP(M7,'Iz''s'!$CP$26:$CT$37,5,FALSE),IF(AND(J7="Alumínio",F7="Trifásico"),VLOOKUP(M7,'Iz''s'!$CP$26:$CT$37,4,FALSE))))) -> 66 | BP7: =IF(AND(J7="Cobre",F7="Monofásico"),VLOOKUP(M7,'Iz''s'!$BL$10:$BS$28,2,FALSE),IF(AND(J7="Cobre",F7="Trifásico"),VLOOKUP(M7,'Iz''s'!$BL$10:$BS$28,3,FALSE),IF(AND(J7="Alumínio",F7="Monofásico"),VLOOKUP(M7,'Iz''s'!$BU$10:$CB$27,2,FALSE),IF(AND(J7="Alumínio",F7="Trifásico"),VLOOKUP(M7,'Iz''s'!$BU$10:$CB$27,3,FALSE))))) -> 54 | BQ7: =IF(AND(J7="Cobre",F7="Monofásico"),VLOOKUP(M7,'Iz''s'!$BL$10:$BS$28,4,FALSE),IF(AND(J7="Cobre",F7="Trifásico"),VLOOKUP(M7,'Iz''s'!$BL$10:$BS$28,5,FALSE),IF(AND(J7="Alumínio",F7="Monofásico"),VLOOKUP(M7,'Iz''s'!$BU$10:$CB$27,4,FALSE),IF(AND(J7="Alumínio",F7="Trifásico"),VLOOKUP(M7,'Iz''s'!$BU$10:$CB$27,5,FALSE))))) -> --- | BR7: =IF(AND(J7="Cobre",F7="Monofásico"),"N/A",IF(AND(J7="Cobre",F7="Trifásico"),VLOOKUP(M7,'Iz''s'!$BL$10:$BS$28,8,FALSE),IF(AND(J7="Alumínio",F7="Monofásico"),"N/A",IF(AND(J7="Alumínio",F7="Trifásico"),VLOOKUP(M7,'Iz''s'!$BU$10:$CB$27,8,FALSE))))) -> --- | BS7: =IF(AND(J7="Cobre",F7="Monofásico"),VLOOKUP(M7,'Iz''s'!$V$14:$Y$28,2,FALSE),IF(AND(J7="Cobre",F7="Trifásico"),VLOOKUP(M7,'Iz''s'!$V$14:$Y$28,3,FALSE),IF(AND(J7="Alumínio",F7="Monofásico"),VLOOKUP(M7,"N/A",4,FALSE),IF(AND(J7="Alumínio",F7="Trifásico"),VLOOKUP(M7,"N/A",4,FALSE))))) -> 48 | BT7: =IF(AND(J7="Cobre",F7="Monofásico"),VLOOKUP(M7,'Iz''s'!$AF$15:$AK$29,2,FALSE),IF(AND(J7="Cobre",F7="Trifásico"),VLOOKUP(M7,'Iz''s'!$AF$15:$AK$29,3,FALSE),IF(AND(J7="Alumínio",F7="Monofásico"),"N/A",IF(AND(J7="Alumínio",F7="Trifásico"),"N/A")))) -> 51 | BU7: =IF(AND(J7="Cobre",F7="Monofásico"),VLOOKUP(M7,'Iz''s'!$AF$15:$AK$29,2,FALSE),IF(AND(J7="Cobre",F7="Trifásico"),VLOOKUP(M7,'Iz''s'!$AF$15:$AK$29,3,FALSE),IF(AND(J7="Alumínio",F7="Monofásico"),"N/A",IF(AND(J7="Alumínio",F7="Trifásico"),"N/A")))) -> 51 | BV7: =IF(AND(J7="Cobre",F7="Monofásico"),"N/A",IF(AND(J7="Cobre",F7="Trifásico"),VLOOKUP(M7,'Iz''s'!$AF$15:$AK$29,6,FALSE),IF(AND(J7="Alumínio",F7="Monofásico"),"N/A",IF(AND(J7="Alumínio",F7="Trifásico"),"N/A")))) -> 71 | BW7: 5 | BY7: =VLOOKUP(M7,Consulta!$W$6:$AB$23,4,FALSE) -> 20 | BZ7: =VLOOKUP(M7,Consulta!$W$6:$AB$23,6,FALSE) -> 25 | CA7: =VLOOKUP(M7,Consulta!$AK$6:$AP$23,4,FALSE) -> 25 | CB7: =VLOOKUP(M7,Consulta!$AK$6:$AP$23,6,FALSE) -> 32 | CC7: =VLOOKUP(M7,Consulta!$AD$6:$AI$19,4,FALSE) -> #N/A | CD7: =VLOOKUP(M7,Consulta!$AD$6:$AI$19,6,FALSE) -> #N/A | CE7: =VLOOKUP(M7,Consulta!$AR$6:$AW$19,4,FALSE) -> #N/A | CF7: =VLOOKUP(M7,Consulta!$AR$6:$AW$19,6,FALSE) -> #N/A
